<robot
  name="igus">
  <link name="world"/>
  
  <joint name="base_joint" type="fixed">
      <origin xyz="0 0 0" rpy="0 0 0"/>
      <parent link="world"/>
      <child link="base_link"/>
  </joint> 

  <link
    name="base_link">
    <inertial>
      <origin
        xyz="-0.0109646724640338 0.0181005963964137 0.0580436521390208"
        rpy="0 0 0" />
      <mass
        value="1.20032441516592" />
      <inertia
        ixx="0.00931932822114558"
        ixy="-1.87296070673386E-05"
        ixz="0.000116424990597675"
        iyy="0.0105088937752615"
        iyz="0.000376007321160209"
        izz="0.0025711861727553" />
    </inertial>
    <visual>
      <origin
        xyz="0 0 0"
        rpy="0 0 0" />
      <geometry>
        <mesh
          filename="package://igus1_description/meshes/base_link.stl" />
      </geometry>
      <material
        name="">
        <color
          rgba="0.752941176470588 0.752941176470588 0.752941176470588 1" />
      </material>
    </visual>
    <collision>
      <origin
        xyz="0 0 0"
        rpy="0 0 0" />
      <geometry>
        <mesh
          filename="package://igus1_description/meshes/base_link.stl" />
      </geometry>
    </collision>
  </link>
  <link
    name="l1">
    <inertial>
      <origin
        xyz="-0.035649 -0.0020132 0.080145"
        rpy="0 0 0" />
      <mass
        value="0.91354" />
      <inertia
        ixx="0.001296"
        ixy="6.7461E-05"
        ixz="-0.00063703"
        iyy="0.0045748"
        iyz="3.3196E-05"
        izz="0.0039438" />
    </inertial>
    <visual>
      <origin
        xyz="0 0 0"
        rpy="0 0 0" />
      <geometry>
        <mesh
          filename="package://igus1_description/meshes/l1.stl" />
      </geometry>
      <material
        name="">
        <color
          rgba="0.75294 0.75294 0.75294 1" />
      </material>
    </visual>
    <collision>
      <origin
        xyz="0 0 0"
        rpy="0 0 0" />
      <geometry>
        <mesh
          filename="package://igus1_description/meshes/l1.stl" />
      </geometry>
    </collision>
  </link>
  <joint
    name="j1"
    type="continuous">
    <origin
      xyz="0 0 0.0667"
      rpy="6.1232E-17 3.6572E-17 1.5708" />
    <parent
      link="base_link" />
    <child
      link="l1" />
    <axis
      xyz="0 0 1" />
  </joint>
  <link
    name="l2">
    <inertial>
      <origin
        xyz="-0.0024353 0.21014 0.0014343"
        rpy="0 0 0" />
      <mass
        value="0.41527" />
      <inertia
        ixx="0.0027253"
        ixy="-0.00024152"
        ixz="-8.3417E-06"
        iyy="0.00037987"
        iyz="-3.4379E-05"
        izz="0.0028171" />
    </inertial>
    <visual>
      <origin
        xyz="0 0 0"
        rpy="0 0 0" />
      <geometry>
        <mesh
          filename="package://igus1_description/meshes/l2.stl" />
      </geometry>
      <material
        name="">
        <color
          rgba="0.75294 0.75294 0.75294 1" />
      </material>
    </visual>
    <collision>
      <origin
        xyz="0 0 0"
        rpy="0 0 0" />
      <geometry>
        <mesh
          filename="package://igus1_description/meshes/l2.stl" />
      </geometry>
    </collision>
  </link>
  <joint
    name="j2"
    type="revolute">
    <origin
      xyz="0 0 0.1007"
      rpy="1.5708 2.4658E-17 3.1823E-18" />
    <parent
      link="l1" />
    <child
      link="l2" />
    <axis
      xyz="0 0 1" />
    <limit
      lower="-0.174533"
      upper="2.53073"
      effort="0"
      velocity="0" />
  </joint>
  <link
    name="l3">
    <inertial>
      <origin
        xyz="-0.0082989 -0.19368 0.0016276"
        rpy="0 0 0" />
      <mass
        value="0.36638" />
      <inertia
        ixx="0.0015567"
        ixy="-0.00022104"
        ixz="7.2976E-06"
        iyy="0.00030829"
        iyz="2.5709E-05"
        izz="0.001655" />
    </inertial>
    <visual>
      <origin
        xyz="0 0 0"
        rpy="0 0 0" />
      <geometry>
        <mesh
          filename="package://igus1_description/meshes/l3.stl" />
      </geometry>
      <material
        name="">
        <color
          rgba="0.75294 0.75294 0.75294 1" />
      </material>
    </visual>
    <collision>
      <origin
        xyz="0 0 0"
        rpy="0 0 0" />
      <geometry>
        <mesh
          filename="package://igus1_description/meshes/l3.stl" />
      </geometry>
    </collision>
  </link>
  <joint
    name="j3"
    type="revolute">
    <origin
      xyz="0.016 0.26953 0"
      rpy="0 0 1.5708" />
    <parent
      link="l2" />
    <child
      link="l3" />
    <axis
      xyz="0 0 1" />
    <limit
      lower="-0.261799"
      upper="2.53073"
      effort="0"
      velocity="0" />
  </joint>
  <link
    name="l4">
    <inertial>
      <origin
        xyz="0.00012521 -0.13067 -0.00012391"
        rpy="0 0 0" />
      <mass
        value="0.15709" />
      <inertia
        ixx="0.00053562"
        ixy="-2.3502E-07"
        ixz="-1.4894E-08"
        iyy="8.2828E-05"
        iyz="6.2888E-07"
        izz="0.0005109" />
    </inertial>
    <visual>
      <origin
        xyz="0 0 0"
        rpy="0 0 0" />
      <geometry>
        <mesh
          filename="package://igus1_description/meshes/l4.stl" />
      </geometry>
      <material
        name="">
        <color
          rgba="0.75294 0.75294 0.75294 1" />
      </material>
    </visual>
    <collision>
      <origin
        xyz="0 0 0"
        rpy="0 0 0" />
      <geometry>
        <mesh
          filename="package://igus1_description/meshes/l4.stl" />
      </geometry>
    </collision>
  </link>
  <joint
    name="j4"
    type="revolute">
    <origin
      xyz="-0.025 -0.23869 0"
      rpy="0 0 -1.5708" />
    <parent
      link="l3" />
    <child
      link="l4" />
    <axis
      xyz="0 0 1" />
    <limit
      lower="-0.261799"
      upper="2.53073"
      effort="0"
      velocity="0" />
  </joint>
  <joint name="ee_joint" type="continuous">
      <parent link="l4" />
      <child link = "ee_link" />
      <origin xyz="0 -0.19 0" rpy="0.0 0.0 1.57" />
  </joint>

  <link name="ee_link">
      <collision>
        <geometry>
          <box size="0.01 0.01 0.01"/>
        </geometry>
        <origin rpy="0 0 0" xyz="0 0 0"/>
      </collision>
</link>
</robot>
